 * Serving Flask app 'mlapp'
 * Debug mode: on
chris@Eva:~/mycode/myProjects/fp$ ./mlapp.py > mlapp.log
WARNING: This is a development server. Do not use it in a production deployment. Use a production WSGI server instead.
 * Running on all addresses (0.0.0.0)
 * Running on http://127.0.0.1:2224
 * Running on http://192.168.1.12:2224
Press CTRL+C to quit
 * Restarting with stat
 * Debugger is active!
 * Debugger PIN: 535-976-207
192.168.1.12 - - [20/Apr/2023 21:43:38] "GET /about HTTP/1.1" 200 -
192.168.1.12 - - [20/Apr/2023 21:43:53] "GET / HTTP/1.1" 200 -
192.168.1.12 - - [20/Apr/2023 21:44:05] "GET /ml_start_pg HTTP/1.1" 500 -
Traceback (most recent call last):
  File "/home/chris/.local/lib/python3.10/site-packages/flask/app.py", line 2551, in __call__
    return self.wsgi_app(environ, start_response)
  File "/home/chris/.local/lib/python3.10/site-packages/flask/app.py", line 2531, in wsgi_app
    response = self.handle_exception(e)
  File "/home/chris/.local/lib/python3.10/site-packages/flask/app.py", line 2528, in wsgi_app
    response = self.full_dispatch_request()
  File "/home/chris/.local/lib/python3.10/site-packages/flask/app.py", line 1825, in full_dispatch_request
    rv = self.handle_user_exception(e)
  File "/home/chris/.local/lib/python3.10/site-packages/flask/app.py", line 1823, in full_dispatch_request
    rv = self.dispatch_request()
  File "/home/chris/.local/lib/python3.10/site-packages/flask/app.py", line 1799, in dispatch_request
    return self.ensure_sync(self.view_functions[rule.endpoint])(**view_args)
  File "/home/chris/mycode/myProjects/fp/mlapp.py", line 35, in ml_start_pg
    return redirect(url_for("app.route", V1 = Verb1, V2 = Verb2))
  File "/home/chris/.local/lib/python3.10/site-packages/flask/helpers.py", line 256, in url_for
    return current_app.url_for(
  File "/home/chris/.local/lib/python3.10/site-packages/flask/app.py", line 2034, in url_for
    return self.handle_url_build_error(error, endpoint, values)
  File "/home/chris/.local/lib/python3.10/site-packages/flask/app.py", line 2023, in url_for
    rv = url_adapter.build(  # type: ignore[union-attr]


  File "/home/chris/.local/lib/python3.10/site-packages/werkzeug/routing/map.py", line 917, in build
    raise BuildError(endpoint, values, method, self)


werkzeug.routing.exceptions.BuildError: Could not build url for endpoint 'app.route' with values ['V1', 'V2']. Did you mean 'about_route' instead?

192.168.1.12 - - [20/Apr/2023 21:44:05] "GET /ml_start_pg?__debugger__=yes&cmd=resource&f=style.css HTTP/1.1" 304 -
192.168.1.12 - - [20/Apr/2023 21:44:05] "GET /ml_start_pg?__debugger__=yes&cmd=resource&f=debugger.js HTTP/1.1" 304 -
192.168.1.12 - - [20/Apr/2023 21:44:05] "GET /ml_start_pg?__debugger__=yes&cmd=resource&f=console.png HTTP/1.1" 304 -
